Workbook
Name IndHolidays: [1]Holidays!$B$2:$B$22
Name IndHolidays: Holidays!$B$2:$B$20

Sheet Current scenario Copy 21Apr
A1: No. | B1: Module | C1: Target page Technology | D1: Recieved Functional & Non Fuctional Walkthrough | E1: Buffer In case of no KT | F1: Module Target Start (Input) | G1: Revised Module Target Start (Input) | H1: Page | I1: Pod | J1: Developer | K1: Start Date | L1: Dev Efforts | M1: Sick/Leave (Input) | N1: PR Number | O1: Co- Pilot Comment Closure Date | P1: Unit Testing Closure Date | Q1: PR raised date | R1: Status | S1: Remarks | T1: PR Response Days | U1: PR Response receive Date | V1: PR Review Comments Fix Days | W1: PR Issue Fix Date | X1: PR Raised Date | Y1: PR Response Days | Z1: PR Response receive Date | AA1: PR Final Approval date | AB1: Code Merge Date (INT Ready) | AC1: TCR Deployment Date | AD1: TCR QE Testing Start Date | AE1: QE Testing Days (TCR) | AF1: TCR QE Testing End Date | AG1: Issue Fix Days | AH1: PR Raise Date | AI1: PR Response Days | AJ1: PR Response receive Date | AK1: New PR Update (Re-deploy) Date | AL1: Code Merge Date (INT Ready) | AM1: TCR QE Testing Start Date | AN1: QE Testing Days (TCR) | AO1: TCR Bugs Closure Date | AP1: Code Freeze Date | AQ1: TEST Deployment | AR1: Pearson Regression Testing/UAT Date | AS1: Pearson Regression Testing Day | AT1: Pearson Regression End Date | AU1: Issue Fix Days | AV1: PR raised date | AW1: PR Response Days | AX1: PR Response receive Date | AY1: Code freeze date = Release cutoff Date | AZ1: Release # | BA1: Release Request Approved Date | BB1: Release Date (2-Wk Cycle) | BC1: Code freeze date = Release cutoff Date | BD1: Elapsed time due to dependencies | BE1: Release alignment lost date | BF1: PR Review days | BG1: Time Lost due to Regression Testing | BH1: Release approval delays | BI1: Total time lost | BJ1: Issue Fix days | BK1: Development efforts can we reduce?
A2: 1 | B2: AddressBook | C2: =VLOOKUP(B2,'Target Tech'!$C$7:$J$33,8,FALSE) -> Complete ASP | D2: Yes | E2: 0 | F2: 46127 | G2: 46127 | H2: page_1 | I2: Pod 1 | J2: Pod 1_Member1 | K2: =F2 -> 46127 | L2: 3 | M2: 0 | N2: 1 | O2: =WORKDAY(K2-1, L2+M2, IndHolidays) -> 46129 | P2: =WORKDAY(K2-1, L2+M2, IndHolidays) -> 46129 | Q2: =WORKDAY(K2-1, L2+M2, IndHolidays) -> 46129 | R2: Completed | T2: 3 | U2: =WORKDAY(Q2, T2, IndHolidays) -> 46134 | V2: 1.5 | W2: =WORKDAY(U2, V2, IndHolidays) -> 46135 | X2: =WORKDAY(W2,0, IndHolidays) -> 46135 | Y2: 3 | Z2: =WORKDAY(X2, Y2, IndHolidays) -> 46140 | AA2: =WORKDAY(Z2, 0, IndHolidays) -> 46140 | AB2: =WORKDAY(AA2, 0, IndHolidays) -> 46140 | AC2: =WORKDAY(AB2, 1, IndHolidays) -> 46141 | AD2: =WORKDAY(AC2, 0, IndHolidays) -> 46141 | AF2: =WORKDAY(AD2, AE2, IndHolidays) -> 46141 | AG2: 2 | AH2: =WORKDAY(AF2, AG2, IndHolidays) -> 46146 | AI2: 3 | AJ2: =WORKDAY(AH2, AI2, IndHolidays) -> 46149 | AK2: =WORKDAY(AJ2, 0, IndHolidays) -> 46149 | AL2: =WORKDAY(AK2, 1, IndHolidays) -> 46150 | AM2: =WORKDAY(AL2, 0, IndHolidays) -> 46150 | AO2: =WORKDAY(AM2, AN2, IndHolidays) -> 46150 | AP2: =AO2 -> 46150 | AQ2: =AP2 -> 46150 | AR2: =WORKDAY(AQ2, 1, IndHolidays) -> 46153 | AT2: =WORKDAY(AR2, AS2, IndHolidays) -> 46153 | AU2: 0 | AV2: =WORKDAY(AT2, AU2, IndHolidays) -> 46153 | AW2: 0 | AX2: =WORKDAY(AV2, AW2, IndHolidays) -> 46153 | AY2: =_xlfn.MINIFS(ReleaseTimeline!$A$2:$A$27, ReleaseTimeline!$A$2:$A$27, ">="&(MAX(AX2,AO2))) -> 46163 | AZ2: =VLOOKUP(AY2,ReleaseTimeline!$A$1:$E$27,2,FALSE) -> Release 11 | BA2: =WORKDAY(AZ2, 2, IndHolidays) -> #VALUE! | BB2: =VLOOKUP(AZ2,ReleaseTimeline!$B$2:$C$27,2,FALSE) -> 46170 | BC2: =VLOOKUP(BA2,ReleaseTimeline!$B$2:$C$27,2,FALSE) -> #VALUE! | BD2: =(BB2 - P2) -> 41 | BF2: =(T2+Y2+AI2+AW2) -> 9
A3: 2 | B3: AddressBook | C3: =VLOOKUP(B3,'Target Tech'!$C$7:$J$33,8,FALSE) -> Complete ASP | D3: Yes | E3: 0 | F3: 46127 | G3: 46127 | H3: page_2 | I3: Pod 1 | J3: Pod 1_Member2 | K3: =F3 -> 46127 | L3: 3 | M3: 0 | N3: 2 | O3: =WORKDAY(K3-1, L3+M3, IndHolidays) -> 46129 | P3: =WORKDAY(K3-1, L3+M3, IndHolidays) -> 46129 | Q3: =WORKDAY(K3-1, L3+M3, IndHolidays) -> 46129 | R3: Completed | T3: 3 | U3: =WORKDAY(Q3, T3, IndHolidays) -> 46134 | V3: 1.5 | W3: =WORKDAY(U3, V3, IndHolidays) -> 46135 | X3: =WORKDAY(W3,0, IndHolidays) -> 46135 | Y3: 3 | Z3: =WORKDAY(X3, Y3, IndHolidays) -> 46140 | AA3: =WORKDAY(Z3, 0, IndHolidays) -> 46140 | AB3: =WORKDAY(AA3, 0, IndHolidays) -> 46140 | AC3: =WORKDAY(AB3, 1, IndHolidays) -> 46141 | AD3: =WORKDAY(AC3, 0, IndHolidays) -> 46141 | AF3: =WORKDAY(AD3, AE3, IndHolidays) -> 46141 | AG3: 2 | AH3: =WORKDAY(AF3, AG3, IndHolidays) -> 46146 | AI3: 3 | AJ3: =WORKDAY(AH3, AI3, IndHolidays) -> 46149 | AK3: =WORKDAY(AJ3, 0, IndHolidays) -> 46149 | AL3: =WORKDAY(AK3, 1, IndHolidays) -> 46150 | AM3: =WORKDAY(AL3, 0, IndHolidays) -> 46150 | AO3: =WORKDAY(AM3, AN3, IndHolidays) -> 46150 | AP3: =AO3 -> 46150 | AQ3: =AP3 -> 46150 | AR3: =WORKDAY(AQ3, 1, IndHolidays) -> 46153 | AT3: =WORKDAY(AR3, AS3, IndHolidays) -> 46153 | AU3: 0 | AV3: =WORKDAY(AT3, AU3, IndHolidays) -> 46153 | AW3: 0 | AX3: =WORKDAY(AV3, AW3, IndHolidays) -> 46153 | AY3: =_xlfn.MINIFS(ReleaseTimeline!$A$2:$A$27, ReleaseTimeline!$A$2:$A$27, ">="&(MAX(AX3,AO3))) -> 46163 | AZ3: =VLOOKUP(AY3,ReleaseTimeline!$A$1:$E$27,2,FALSE) -> Release 11 | BA3: =WORKDAY(AZ3, 2, IndHolidays) -> #VALUE! | BB3: =VLOOKUP(AZ3,ReleaseTimeline!$B$2:$C$27,2,FALSE) -> 46170 | BC3: =WORKDAY(BB3, -5) -> 46163 | BD3: =(BB3 - P3) -> 41 | BF3: =(T3+Y3+AI3+AW3) -> 9
A4: 3 | B4: AddressBook | C4: =VLOOKUP(B4,'Target Tech'!$C$7:$J$33,8,FALSE) -> Complete ASP | D4: Yes | E4: 0 | F4: 46127 | G4: 46127 | H4: page_3 | I4: Pod 1 | J4: Pod 1_Member3 | K4: =F4 -> 46127 | L4: 3 | M4: 0 | N4: 3 | O4: =WORKDAY(K4-1, L4+M4, IndHolidays) -> 46129 | P4: =WORKDAY(K4-1, L4+M4, IndHolidays) -> 46129 | Q4: =WORKDAY(K4-1, L4+M4, IndHolidays) -> 46129 | R4: Completed | T4: 3 | U4: =WORKDAY(Q4, T4, IndHolidays) -> 46134 | V4: 1.5 | W4: =WORKDAY(U4, V4, IndHolidays) -> 46135 | X4: =WORKDAY(W4,0, IndHolidays) -> 46135 | Y4: 3 | Z4: =WORKDAY(X4, Y4, IndHolidays) -> 46140 | AA4: =WORKDAY(Z4, 0, IndHolidays) -> 46140 | AB4: =WORKDAY(AA4, 0, IndHolidays) -> 46140 | AC4: =WORKDAY(AB4, 1, IndHolidays) -> 46141 | AD4: =WORKDAY(AC4, 0, IndHolidays) -> 46141 | AF4: =WORKDAY(AD4, AE4, IndHolidays) -> 46141 | AG4: 2 | AH4: =WORKDAY(AF4, AG4, IndHolidays) -> 46146 | AI4: 3 | AJ4: =WORKDAY(AH4, AI4, IndHolidays) -> 46149 | AK4: =WORKDAY(AJ4, 0, IndHolidays) -> 46149 | AL4: =WORKDAY(AK4, 1, IndHolidays) -> 46150 | AM4: =WORKDAY(AL4, 0, IndHolidays) -> 46150 | AO4: =WORKDAY(AM4, AN4, IndHolidays) -> 46150 | AP4: =AO4 -> 46150 | AQ4: =AP4 -> 46150 | AR4: =WORKDAY(AQ4, 1, IndHolidays) -> 46153 | AT4: =WORKDAY(AR4, AS4, IndHolidays) -> 46153 | AU4: 0 | AV4: =WORKDAY(AT4, AU4, IndHolidays) -> 46153 | AW4: 0 | AX4: =WORKDAY(AV4, AW4, IndHolidays) -> 46153 | AY4: =_xlfn.MINIFS(ReleaseTimeline!$A$2:$A$27, ReleaseTimeline!$A$2:$A$27, ">="&(MAX(AX4,AO4))) -> 46163 | AZ4: =VLOOKUP(AY4,ReleaseTimeline!$A$1:$E$27,2,FALSE) -> Release 11 | BA4: =WORKDAY(AZ4, 2, IndHolidays) -> #VALUE! | BB4: =VLOOKUP(AZ4,ReleaseTimeline!$B$2:$C$27,2,FALSE) -> 46170 | BC4: =WORKDAY(BB4, -5) -> 46163 | BD4: =(BB4 - P4) -> 41 | BF4: =(T4+Y4+AI4+AW4) -> 9
A5: 4 | B5: AddressBook | C5: =VLOOKUP(B5,'Target Tech'!$C$7:$J$33,8,FALSE) -> Complete ASP | D5: Yes | E5: 0 | F5: 46132 | G5: 46132 | H5: page_4 | I5: Pod 1 | J5: Pod 1_Member1 | K5: =F5 -> 46132 | L5: 3 | M5: 0 | N5: 4 | O5: =WORKDAY(K5-1, L5+M5, IndHolidays) -> 46134 | P5: =WORKDAY(K5-1, L5+M5, IndHolidays) -> 46134 | Q5: =WORKDAY(K5-1, L5+M5, IndHolidays) -> 46134 | R5: Completed | T5: 3 | U5: =WORKDAY(Q5, T5, IndHolidays) -> 46139 | V5: 1.5 | W5: =WORKDAY(U5, V5, IndHolidays) -> 46140 | X5: =WORKDAY(W5,0, IndHolidays) -> 46140 | Y5: 3 | Z5: =WORKDAY(X5, Y5, IndHolidays) -> 46146 | AA5: =WORKDAY(Z5, 0, IndHolidays) -> 46146 | AB5: =WORKDAY(AA5, 0, IndHolidays) -> 46146 | AC5: =WORKDAY(AB5, 1, IndHolidays) -> 46147 | AD5: =WORKDAY(AC5, 0, IndHolidays) -> 46147 | AF5: =WORKDAY(AD5, AE5, IndHolidays) -> 46147 | AG5: 2 | AH5: =WORKDAY(AF5, AG5, IndHolidays) -> 46149 | AI5: 3 | AJ5: =WORKDAY(AH5, AI5, IndHolidays) -> 46154 | AK5: =WORKDAY(AJ5, 0, IndHolidays) -> 46154 | AL5: =WORKDAY(AK5, 1, IndHolidays) -> 46155 | AM5: =WORKDAY(AL5, 0, IndHolidays) -> 46155 | AO5: =WORKDAY(AM5, AN5, IndHolidays) -> 46155 | AP5: =AO5 -> 46155 | AQ5: =AP5 -> 46155 | AR5: =WORKDAY(AQ5, 1, IndHolidays) -> 46156 | AT5: =WORKDAY(AR5, AS5, IndHolidays) -> 46156 | AU5: 0 | AV5: =WORKDAY(AT5, AU5, IndHolidays) -> 46156 | AW5: 0 | AX5: =WORKDAY(AV5, AW5, IndHolidays) -> 46156 | AY5: =_xlfn.MINIFS(ReleaseTimeline!$A$2:$A$27, ReleaseTimeline!$A$2:$A$27, ">="&(MAX(AX5,AO5))) -> 46163 | AZ5: =VLOOKUP(AY5,ReleaseTimeline!$A$1:$E$27,2,FALSE) -> Release 11 | BA5: =WORKDAY(AZ5, 2, IndHolidays) -> #VALUE! | BB5: =VLOOKUP(AZ5,ReleaseTimeline!$B$2:$C$27,2,FALSE) -> 46170 | BC5: =WORKDAY(BB5, -5) -> 46163 | BD5: =(BB5 - P5) -> 36 | BF5: =(T5+Y5+AI5+AW5) -> 9
A6: 5 | B6: AddressBook | C6: =VLOOKUP(B6,'Target Tech'!$C$7:$J$33,8,FALSE) -> Complete ASP | D6: Yes | E6: 0 | F6: 46132 | G6: 46132 | H6: page_5 | I6: Pod 1 | J6: Pod 1_Member2 | K6: =F6 -> 46132 | L6: 3 | M6: 0 | N6: 5 | O6: =WORKDAY(K6-1, L6+M6, IndHolidays) -> 46134 | P6: =WORKDAY(K6-1, L6+M6, IndHolidays) -> 46134 | Q6: =WORKDAY(K6-1, L6+M6, IndHolidays) -> 46134 | R6: Completed | T6: 3 | U6: =WORKDAY(Q6, T6, IndHolidays) -> 46139 | V6: 1.5 | W6: =WORKDAY(U6, V6, IndHolidays) -> 46140 | X6: =WORKDAY(W6,0, IndHolidays) -> 46140 | Y6: 3 | Z6: =WORKDAY(X6, Y6, IndHolidays) -> 46146 | AA6: =WORKDAY(Z6, 0, IndHolidays) -> 46146 | AB6: =WORKDAY(AA6, 0, IndHolidays) -> 46146 | AC6: =WORKDAY(AB6, 1, IndHolidays) -> 46147 | AD6: =WORKDAY(AC6, 0, IndHolidays) -> 46147 | AE6: 3 | AF6: =WORKDAY(AD6, AE6, IndHolidays) -> 46150 | AG6: 2 | AH6: =WORKDAY(AF6, AG6, IndHolidays) -> 46154 | AI6: 3 | AJ6: =WORKDAY(AH6, AI6, IndHolidays) -> 46157 | AK6: =WORKDAY(AJ6, 0, IndHolidays) -> 46157 | AL6: =WORKDAY(AK6, 1, IndHolidays) -> 46160 | AM6: =WORKDAY(AL6, 0, IndHolidays) -> 46160 | AN6: 1 | AO6: =WORKDAY(AM6, AN6, IndHolidays) -> 46161 | AP6: =AO6 -> 46161 | AQ6: =AP6 -> 46161 | AR6: =WORKDAY(AQ6, 1, IndHolidays) -> 46162 | AS6: 3 | AT6: =WORKDAY(AR6, AS6, IndHolidays) -> 46167 | AU6: 0 | AV6: =WORKDAY(AT6, AU6, IndHolidays) -> 46167 | AW6: 0 | AX6: =WORKDAY(AV6, AW6, IndHolidays) -> 46167 | AY6: =_xlfn.MINIFS(ReleaseTimeline!$A$2:$A$27, ReleaseTimeline!$A$2:$A$27, ">="&(MAX(AX6,AO6))) -> 46177 | AZ6: =VLOOKUP(AY6,ReleaseTimeline!$A$1:$E$27,2,FALSE) -> Release 12 | BA6: =WORKDAY(AZ6, 2, IndHolidays) -> #VALUE! | BB6: =VLOOKUP(AZ6,ReleaseTimeline!$B$2:$C$27,2,FALSE) -> 46184 | BC6: =WORKDAY(BB6, -5) -> 46177 | BD6: =(BB6 - P6) -> 50 | BE6: =(BB6-AZ6) -> #VALUE! | BF6: =(T6+Y6+AI6+AW6) -> 9 | BI6: =(BE6+BF6) -> #VALUE!
A7: 6 | B7: Assessments | C7: =VLOOKUP(B7,'Target Tech'!$C$7:$J$33,8,FALSE) -> Complete ASP | D7: Yes | E7: 0 | F7: 46127 | G7: 46134 | H7: assessments\results\manager.aspx.cs | I7: Pod 2 | J7: Vijay | K7: 46136 | L7: 3 | M7: 0 | N7: 1 | O7: =WORKDAY(K7-1, L7+M7, IndHolidays) -> 46140 | P7: =WORKDAY(K7-1, L7+M7, IndHolidays) -> 46140 | Q7: =WORKDAY(K7-1, L7+M7, IndHolidays) -> 46140 | R7: On track | S7: Dev in progress, PR will be raisd on 28th Apr | T7: 3 | U7: =WORKDAY(Q7, T7, IndHolidays) -> 46146 | V7: 1.5 | W7: =WORKDAY(U7, V7, IndHolidays) -> 46147 | X7: =WORKDAY(W7,0, IndHolidays) -> 46147 | Y7: 3 | Z7: =WORKDAY(X7, Y7, IndHolidays) -> 46150 | AA7: =WORKDAY(Z7, 0, IndHolidays) -> 46150 | AB7: =WORKDAY(AA7, 0, IndHolidays) -> 46150 | AC7: =WORKDAY(AB7, 1, IndHolidays) -> 46153 | AD7: =WORKDAY(AC7, 0, IndHolidays) -> 46153 | AF7: =WORKDAY(AD7, AE7, IndHolidays) -> 46153 | AG7: 2 | AH7: =WORKDAY(AF7, AG7, IndHolidays) -> 46155 | AI7: 3 | AJ7: =WORKDAY(AH7, AI7, IndHolidays) -> 46160 | AK7: =WORKDAY(AJ7, 0, IndHolidays) -> 46160 | AL7: =WORKDAY(AK7, 1, IndHolidays) -> 46161 | AM7: =WORKDAY(AL7, 0, IndHolidays) -> 46161 | AO7: =WORKDAY(AM7, AN7, IndHolidays) -> 46161 | AP7: =AO7 -> 46161 | AQ7: =AP7 -> 46161 | AR7: =WORKDAY(AQ7, 1, IndHolidays) -> 46162 | AT7: =WORKDAY(AR7, AS7, IndHolidays) -> 46162 | AU7: 0 | AV7: =WORKDAY(AT7, AU7, IndHolidays) -> 46162 | AW7: 0 | AX7: =WORKDAY(AV7, AW7, IndHolidays) -> 46162 | AY7: =_xlfn.MINIFS(ReleaseTimeline!$A$2:$A$27, ReleaseTimeline!$A$2:$A$27, ">="&(MAX(AX7,AO7))) -> 46163 | AZ7: =VLOOKUP(AY7,ReleaseTimeline!$A$1:$E$27,2,FALSE) -> Release 11 | BA7: =WORKDAY(AZ7, 3, IndHolidays) -> #VALUE! | BB7: =VLOOKUP(AZ7,ReleaseTimeline!$B$2:$C$27,2,FALSE) -> 46170 | BC7: =WORKDAY(BB7, -5) -> 46163 | BD7: =(BB7 - P7) -> 30 | BF7: =(T7+Y7+AI7+AW7) -> 9
A8: 7 | B8: Assessments | C8: =VLOOKUP(B8,'Target Tech'!$C$7:$J$33,8,FALSE) -> Complete ASP | D8: Yes | E8: 0 | F8: 46127 | G8: 46134 | H8: assessments\results\listtaken.aspx.cs | I8: Pod 2 | J8: Sohith | K8: 46136 | L8: 3 | M8: 0 | N8: 2 | O8: =WORKDAY(K8-1, L8+M8, IndHolidays) -> 46140 | P8: =WORKDAY(K8-1, L8+M8, IndHolidays) -> 46140 | Q8: =WORKDAY(K8-1, L8+M8, IndHolidays) -> 46140 | R8: On track | S8: Dev in progress, PR will be raisd on 28th Apr Kept on hold on 28th Apr as we were raised PR for shared controls. | T8: 3 | U8: =WORKDAY(Q8, T8, IndHolidays) -> 46146 | V8: 1.5 | W8: =WORKDAY(U8, V8, IndHolidays) -> 46147 | X8: =WORKDAY(W8,0, IndHolidays) -> 46147 | Y8: 3 | Z8: =WORKDAY(X8, Y8, IndHolidays) -> 46150 | AA8: =WORKDAY(Z8, 0, IndHolidays) -> 46150 | AB8: =WORKDAY(AA8, 0, IndHolidays) -> 46150 | AC8: =WORKDAY(AB8, 1, IndHolidays) -> 46153 | AD8: =WORKDAY(AC8, 0, IndHolidays) -> 46153 | AF8: =WORKDAY(AD8, AE8, IndHolidays) -> 46153 | AG8: 2 | AH8: =WORKDAY(AF8, AG8, IndHolidays) -> 46155 | AI8: 3 | AJ8: =WORKDAY(AH8, AI8, IndHolidays) -> 46160 | AK8: =WORKDAY(AJ8, 0, IndHolidays) -> 46160 | AL8: =WORKDAY(AK8, 1, IndHolidays) -> 46161 | AM8: =WORKDAY(AL8, 0, IndHolidays) -> 46161 | AO8: =WORKDAY(AM8, AN8, IndHolidays) -> 46161 | AP8: =AO8 -> 46161 | AQ8: =AP8 -> 46161 | AR8: =WORKDAY(AQ8, 1, IndHolidays) -> 46162 | AT8: =WORKDAY(AR8, AS8, IndHolidays) -> 46162 | AU8: 0 | AV8: =WORKDAY(AT8, AU8, IndHolidays) -> 46162 | AW8: 0 | AX8: =WORKDAY(AV8, AW8, IndHolidays) -> 46162 | AY8: =_xlfn.MINIFS(ReleaseTimeline!$A$2:$A$27, ReleaseTimeline!$A$2:$A$27, ">="&(MAX(AX8,AO8))) -> 46163 | AZ8: =VLOOKUP(AY8,ReleaseTimeline!$A$1:$E$27,2,FALSE) -> Release 11 | BA8: =WORKDAY(AZ8, 3, IndHolidays) -> #VALUE! | BB8: =VLOOKUP(AZ8,ReleaseTimeline!$B$2:$C$27,2,FALSE) -> 46170 | BC8: =WORKDAY(BB8, -5) -> 46163 | BD8: =(BB8 - P8) -> 30 | BF8: =(T8+Y8+AI8+AW8) -> 9
A9: 8 | B9: Assessments | C9: =VLOOKUP(B9,'Target Tech'!$C$7:$J$33,8,FALSE) -> Complete ASP | D9: Yes | E9: 0 | F9: 46127 | G9: 46134 | H9: assessments\reports\assessmentQuestionAnalysis.aspx.cs | I9: Pod 2 | J9: Anil | K9: 46136 | L9: 3 | M9: 0 | N9: 3 | O9: =WORKDAY(K9-1, L9+M9, IndHolidays) -> 46140 | P9: =WORKDAY(K9-1, L9+M9, IndHolidays) -> 46140 | Q9: =WORKDAY(K9-1, L9+M9, IndHolidays) -> 46140 | S9: Dev completed however facing UI issues. fix in progress. | T9: 3 | U9: =WORKDAY(Q9, T9, IndHolidays) -> 46146 | V9: 1.5 | W9: =WORKDAY(U9, V9, IndHolidays) -> 46147 | X9: =WORKDAY(W9,0, IndHolidays) -> 46147 | Y9: 3 | Z9: =WORKDAY(X9, Y9, IndHolidays) -> 46150 | AA9: =WORKDAY(Z9, 0, IndHolidays) -> 46150 | AB9: =WORKDAY(AA9, 0, IndHolidays) -> 46150 | AC9: =WORKDAY(AB9, 1, IndHolidays) -> 46153 | AD9: =WORKDAY(AC9, 0, IndHolidays) -> 46153 | AF9: =WORKDAY(AD9, AE9, IndHolidays) -> 46153 | AG9: 2 | AH9: =WORKDAY(AF9, AG9, IndHolidays) -> 46155 | AI9: 3 | AJ9: =WORKDAY(AH9, AI9, IndHolidays) -> 46160 | AK9: =WORKDAY(AJ9, 0, IndHolidays) -> 46160 | AL9: =WORKDAY(AK9, 1, IndHolidays) -> 46161 | AM9: =WORKDAY(AL9, 0, IndHolidays) -> 46161 | AO9: =WORKDAY(AM9, AN9, IndHolidays) -> 46161 | AP9: =AO9 -> 46161 | AQ9: =AP9 -> 46161 | AR9: =WORKDAY(AQ9, 1, IndHolidays) -> 46162 | AT9: =WORKDAY(AR9, AS9, IndHolidays) -> 46162 | AU9: 0 | AV9: =WORKDAY(AT9, AU9, IndHolidays) -> 46162 | AW9: 0 | AX9: =WORKDAY(AV9, AW9, IndHolidays) -> 46162 | AY9: =_xlfn.MINIFS(ReleaseTimeline!$A$2:$A$27, ReleaseTimeline!$A$2:$A$27, ">="&(MAX(AX9,AO9))) -> 46163 | AZ9: =VLOOKUP(AY9,ReleaseTimeline!$A$1:$E$27,2,FALSE) -> Release 11 | BA9: =WORKDAY(AZ9, 3, IndHolidays) -> #VALUE! | BB9: =VLOOKUP(AZ9,ReleaseTimeline!$B$2:$C$27,2,FALSE) -> 46170 | BC9: =WORKDAY(BB9, -5) -> 46163 | BD9: =(BB9 - P9) -> 30 | BF9: =(T9+Y9+AI9+AW9) -> 9
A10: 9 | B10: Assessments | C10: =VLOOKUP(B10,'Target Tech'!$C$7:$J$33,8,FALSE) -> Complete ASP | D10: Yes | E10: 0 | F10: 46132 | G10: 46146 | H10: assessments\import.aspx.cs | I10: Pod 2 | J10: Anil | K10: 46146 | L10: 3 | M10: 0 | N10: 4 | O10: =WORKDAY(K10-1, L10+M10, IndHolidays) -> 46148 | P10: =WORKDAY(K10-1, L10+M10, IndHolidays) -> 46148 | Q10: =WORKDAY(K10-1, L10+M10, IndHolidays) -> 46148 | T10: 3 | U10: =WORKDAY(Q10, T10, IndHolidays) -> 46153 | V10: 1.5 | W10: =WORKDAY(U10, V10, IndHolidays) -> 46154 | X10: =WORKDAY(W10,0, IndHolidays) -> 46154 | Y10: 3 | Z10: =WORKDAY(X10, Y10, IndHolidays) -> 46157 | AA10: =WORKDAY(Z10, 0, IndHolidays) -> 46157 | AB10: =WORKDAY(AA10, 0, IndHolidays) -> 46157 | AC10: =WORKDAY(AB10, 1, IndHolidays) -> 46160 | AD10: =WORKDAY(AC10, 0, IndHolidays) -> 46160 | AF10: =WORKDAY(AD10, AE10, IndHolidays) -> 46160 | AG10: 2 | AH10: =WORKDAY(AF10, AG10, IndHolidays) -> 46162 | AI10: 3 | AJ10: =WORKDAY(AH10, AI10, IndHolidays) -> 46167 | AK10: =WORKDAY(AJ10, 0, IndHolidays) -> 46167 | AL10: =WORKDAY(AK10, 1, IndHolidays) -> 46168 | AM10: =WORKDAY(AL10, 0, IndHolidays) -> 46168 | AO10: =WORKDAY(AM10, AN10, IndHolidays) -> 46168 | AP10: =AO10 -> 46168 | AQ10: =AP10 -> 46168 | AR10: =WORKDAY(AQ10, 1, IndHolidays) -> 46169 | AT10: =WORKDAY(AR10, AS10, IndHolidays) -> 46169 | AU10: 0 | AV10: =WORKDAY(AT10, AU10, IndHolidays) -> 46169 | AW10: 0 | AX10: =WORKDAY(AV10, AW10, IndHolidays) -> 46169 | AY10: =_xlfn.MINIFS(ReleaseTimeline!$A$2:$A$27, ReleaseTimeline!$A$2:$A$27, ">="&(MAX(AX10,AO10))) -> 46177 | AZ10: =VLOOKUP(AY10,ReleaseTimeline!$A$1:$E$27,2,FALSE) -> Release 12 | BA10: =WORKDAY(AZ10, 3, IndHolidays) -> #VALUE! | BB10: =VLOOKUP(AZ10,ReleaseTimeline!$B$2:$C$27,2,FALSE) -> 46184 | BC10: =WORKDAY(BB10, -5) -> 46177 | BD10: =(BB10 - P10) -> 36 | BF10: =(T10+Y10+AI10+AW10) -> 9
A11: 10 | B11: Assessments | C11: =VLOOKUP(B11,'Target Tech'!$C$7:$J$33,8,FALSE) -> Complete ASP | D11: Yes | E11: 0 | F11: 46132 | G11: 46146 | H11: assessments\assessment.aspx.cs | I11: Pod 2 | J11: Sohith | K11: 46146 | L11: 3 | M11: 0 | N11: 5 | O11: =WORKDAY(K11-1, L11+M11, IndHolidays) -> 46148 | P11: =WORKDAY(K11-1, L11+M11, IndHolidays) -> 46148 | Q11: =WORKDAY(K11-1, L11+M11, IndHolidays) -> 46148 | T11: 3 | U11: =WORKDAY(Q11, T11, IndHolidays) -> 46153 | V11: 1.5 | W11: =WORKDAY(U11, V11, IndHolidays) -> 46154 | X11: =WORKDAY(W11,0, IndHolidays) -> 46154 | Y11: 3 | Z11: =WORKDAY(X11, Y11, IndHolidays) -> 46157 | AA11: =WORKDAY(Z11, 0, IndHolidays) -> 46157 | AB11: =WORKDAY(AA11, 0, IndHolidays) -> 46157 | AC11: =WORKDAY(AB11, 1, IndHolidays) -> 46160 | AD11: =WORKDAY(AC11, 0, IndHolidays) -> 46160 | AF11: =WORKDAY(AD11, AE11, IndHolidays) -> 46160 | AG11: 2 | AH11: =WORKDAY(AF11, AG11, IndHolidays) -> 46162 | AI11: 3 | AJ11: =WORKDAY(AH11, AI11, IndHolidays) -> 46167 | AK11: =WORKDAY(AJ11, 0, IndHolidays) -> 46167 | AL11: =WORKDAY(AK11, 1, IndHolidays) -> 46168 | AM11: =WORKDAY(AL11, 0, IndHolidays) -> 46168 | AO11: =WORKDAY(AM11, AN11, IndHolidays) -> 46168 | AP11: =AO11 -> 46168 | AQ11: =AP11 -> 46168 | AR11: =WORKDAY(AQ11, 1, IndHolidays) -> 46169 | AT11: =WORKDAY(AR11, AS11, IndHolidays) -> 46169 | AU11: 0 | AV11: =WORKDAY(AT11, AU11, IndHolidays) -> 46169 | AW11: 0 | AX11: =WORKDAY(AV11, AW11, IndHolidays) -> 46169 | AY11: =_xlfn.MINIFS(ReleaseTimeline!$A$2:$A$27, ReleaseTimeline!$A$2:$A$27, ">="&(MAX(AX11,AO11))) -> 46177 | AZ11: =VLOOKUP(AY11,ReleaseTimeline!$A$1:$E$27,2,FALSE) -> Release 12 | BA11: =WORKDAY(AZ11, 3, IndHolidays) -> #VALUE! | BB11: =VLOOKUP(AZ11,ReleaseTimeline!$B$2:$C$27,2,FALSE) -> 46184 | BC11: =WORKDAY(BB11, -5) -> 46177 | BD11: =(BB11 - P11) -> 36 | BF11: =(T11+Y11+AI11+AW11) -> 9
A12: 11 | B12: Assessments | C12: =VLOOKUP(B12,'Target Tech'!$C$7:$J$33,8,FALSE) -> Complete ASP | D12: Yes | E12: 0 | F12: 46132 | G12: 46140 | H12: assessments\reports\assessmentAnswersAccepted.aspx.cs | I12: Pod 2 | J12: Anil | K12: 46136 | L12: 3 | M12: 0 | N12: 6 | O12: =WORKDAY(K12-1, L12+M12, IndHolidays) -> 46140 | P12: =WORKDAY(K12-1, L12+M12, IndHolidays) -> 46140 | Q12: =WORKDAY(K12-1, L12+M12, IndHolidays) -> 46140 | S12: Dev completed however facing UI issues. fix in progress. | T12: 3 | U12: =WORKDAY(Q12, T12, IndHolidays) -> 46146 | V12: 1.5 | W12: =WORKDAY(U12, V12, IndHolidays) -> 46147 | X12: =WORKDAY(W12,0, IndHolidays) -> 46147 | Y12: 3 | Z12: =WORKDAY(X12, Y12, IndHolidays) -> 46150 | AA12: =WORKDAY(Z12, 0, IndHolidays) -> 46150 | AB12: =WORKDAY(AA12, 0, IndHolidays) -> 46150 | AC12: =WORKDAY(AB12, 1, IndHolidays) -> 46153 | AD12: =WORKDAY(AC12, 0, IndHolidays) -> 46153 | AF12: =WORKDAY(AD12, AE12, IndHolidays) -> 46153 | AG12: 2 | AH12: =WORKDAY(AF12, AG12, IndHolidays) -> 46155 | AI12: 3 | AJ12: =WORKDAY(AH12, AI12, IndHolidays) -> 46160 | AK12: =WORKDAY(AJ12, 0, IndHolidays) -> 46160 | AL12: =WORKDAY(AK12, 1, IndHolidays) -> 46161 | AM12: =WORKDAY(AL12, 0, IndHolidays) -> 46161 | AO12: =WORKDAY(AM12, AN12, IndHolidays) -> 46161 | AP12: =AO12 -> 46161 | AQ12: =AP12 -> 46161 | AR12: =WORKDAY(AQ12, 1, IndHolidays) -> 46162 | AT12: =WORKDAY(AR12, AS12, IndHolidays) -> 46162 | AU12: 0 | AV12: =WORKDAY(AT12, AU12, IndHolidays) -> 46162 | AW12: 0 | AX12: =WORKDAY(AV12, AW12, IndHolidays) -> 46162 | AY12: =_xlfn.MINIFS(ReleaseTimeline!$A$2:$A$27, ReleaseTimeline!$A$2:$A$27, ">="&(MAX(AX12,AO12))) -> 46163 | AZ12: =VLOOKUP(AY12,ReleaseTimeline!$A$1:$E$27,2,FALSE) -> Release 11 | BA12: =WORKDAY(AZ12, 3, IndHolidays) -> #VALUE! | BB12: =VLOOKUP(AZ12,ReleaseTimeline!$B$2:$C$27,2,FALSE) -> 46170 | BC12: =WORKDAY(BB12, -5) -> 46163 | BD12: =(BB12 - P12) -> 30 | BF12: =(T12+Y12+AI12+AW12) -> 9
A13: 12 | B13: Assessments | C13: =VLOOKUP(B13,'Target Tech'!$C$7:$J$33,8,FALSE) -> Complete ASP | D13: Yes | E13: 0 | F13: 46136 | G13: 46146 | H13: assessments\default.aspx.cs | I13: Pod 3 | J13: Vijay | K13: 46146 | L13: 3 | M13: 0 | N13: 7 | O13: =WORKDAY(K13-1, L13+M13, IndHolidays) -> 46148 | P13: =WORKDAY(K13-1, L13+M13, IndHolidays) -> 46148 | Q13: =WORKDAY(K13-1, L13+M13, IndHolidays) -> 46148 | T13: 3 | U13: =WORKDAY(Q13, T13, IndHolidays) -> 46153 | V13: 1.5 | W13: =WORKDAY(U13, V13, IndHolidays) -> 46154 | X13: =WORKDAY(W13,0, IndHolidays) -> 46154 | Y13: 3 | Z13: =WORKDAY(X13, Y13, IndHolidays) -> 46157 | AA13: =WORKDAY(Z13, 0, IndHolidays) -> 46157 | AB13: =WORKDAY(AA13, 0, IndHolidays) -> 46157 | AC13: =WORKDAY(AB13, 1, IndHolidays) -> 46160 | AD13: =WORKDAY(AC13, 0, IndHolidays) -> 46160 | AF13: =WORKDAY(AD13, AE13, IndHolidays) -> 46160 | AG13: 2 | AH13: =WORKDAY(AF13, AG13, IndHolidays) -> 46162 | AI13: 3 | AJ13: =WORKDAY(AH13, AI13, IndHolidays) -> 46167 | AK13: =WORKDAY(AJ13, 0, IndHolidays) -> 46167 | AL13: =WORKDAY(AK13, 1, IndHolidays) -> 46168 | AM13: =WORKDAY(AL13, 0, IndHolidays) -> 46168 | AO13: =WORKDAY(AM13, AN13, IndHolidays) -> 46168 | AP13: =AO13 -> 46168 | AQ13: =AP13 -> 46168 | AR13: =WORKDAY(AQ13, 1, IndHolidays) -> 46169 | AT13: =WORKDAY(AR13, AS13, IndHolidays) -> 46169 | AU13: 0 | AV13: =WORKDAY(AT13, AU13, IndHolidays) -> 46169 | AW13: 0 | AX13: =WORKDAY(AV13, AW13, IndHolidays) -> 46169 | AY13: =_xlfn.MINIFS(ReleaseTimeline!$A$2:$A$27, ReleaseTimeline!$A$2:$A$27, ">="&(MAX(AX13,AO13))) -> 46177 | AZ13: =VLOOKUP(AY13,ReleaseTimeline!$A$1:$E$27,2,FALSE) -> Release 12 | BA13: =WORKDAY(AZ13, 3, IndHolidays) -> #VALUE! | BB13: =VLOOKUP(AZ13,ReleaseTimeline!$B$2:$C$27,2,FALSE) -> 46184 | BC13: =WORKDAY(BB13, -5) -> 46177 | BD13: =(BB13 - P13) -> 36 | BF13: =(T13+Y13+AI13+AW13) -> 9
A14: 13 | B14: Assessments | C14: =VLOOKUP(B14,'Target Tech'!$C$7:$J$33,8,FALSE) -> Complete ASP | D14: Yes | E14: 0 | F14: 46136 | G14: 46146 | H14: assessments\checkMyWork\submissions.aspx.cs | I14: Pod 3 | J14: Sohith | K14: 46146 | L14: 3 | M14: 0 | N14: 8 | O14: =WORKDAY(K14-1, L14+M14, IndHolidays) -> 46148 | P14: =WORKDAY(K14-1, L14+M14, IndHolidays) -> 46148 | Q14: =WORKDAY(K14-1, L14+M14, IndHolidays) -> 46148 | T14: 3 | U14: =WORKDAY(Q14, T14, IndHolidays) -> 46153 | V14: 1.5 | W14: =WORKDAY(U14, V14, IndHolidays) -> 46154 | X14: =WORKDAY(W14,0, IndHolidays) -> 46154 | Y14: 3 | Z14: =WORKDAY(X14, Y14, IndHolidays) -> 46157 | AA14: =WORKDAY(Z14, 0, IndHolidays) -> 46157 | AB14: =WORKDAY(AA14, 0, IndHolidays) -> 46157 | AC14: =WORKDAY(AB14, 1, IndHolidays) -> 46160 | AD14: =WORKDAY(AC14, 0, IndHolidays) -> 46160 | AF14: =WORKDAY(AD14, AE14, IndHolidays) -> 46160 | AG14: 2 | AH14: =WORKDAY(AF14, AG14, IndHolidays) -> 46162 | AI14: 3 | AJ14: =WORKDAY(AH14, AI14, IndHolidays) -> 46167 | AK14: =WORKDAY(AJ14, 0, IndHolidays) -> 46167 | AL14: =WORKDAY(AK14, 1, IndHolidays) -> 46168 | AM14: =WORKDAY(AL14, 0, IndHolidays) -> 46168 | AO14: =WORKDAY(AM14, AN14, IndHolidays) -> 46168 | AP14: =AO14 -> 46168 | AQ14: =AP14 -> 46168 | AR14: =WORKDAY(AQ14, 1, IndHolidays) -> 46169 | AT14: =WORKDAY(AR14, AS14, IndHolidays) -> 46169 | AU14: 0 | AV14: =WORKDAY(AT14, AU14, IndHolidays) -> 46169 | AW14: 0 | AX14: =WORKDAY(AV14, AW14, IndHolidays) -> 46169 | AY14: =_xlfn.MINIFS(ReleaseTimeline!$A$2:$A$27, ReleaseTimeline!$A$2:$A$27, ">="&(MAX(AX14,AO14))) -> 46177 | AZ14: =VLOOKUP(AY14,ReleaseTimeline!$A$1:$E$27,2,FALSE) -> Release 12 | BA14: =WORKDAY(AZ14, 3, IndHolidays) -> #VALUE! | BB14: =VLOOKUP(AZ14,ReleaseTimeline!$B$2:$C$27,2,FALSE) -> 46184 | BC14: =WORKDAY(BB14, -5) -> 46177 | BD14: =(BB14 - P14) -> 36 | BE14: =(BB14-AZ14) -> #VALUE! | BF14: =(T14+Y14+AI14+AW14) -> 9 | BI14: =(BE14+BF14) -> #VALUE!
A15: 14 | B15: Assessments | C15: =VLOOKUP(B15,'Target Tech'!$C$7:$J$33,8,FALSE) -> Complete ASP | D15: Yes | E15: 0 | F15: 46136 | G15: 46143 | H15: assessments/reports/assessmentAnalysis | I15: Pod 3 | J15: Anil | K15: 46135 | L15: 3 | M15: 0 | N15: 9 | O15: =WORKDAY(K15-1, L15+M15, IndHolidays) -> 46139 | P15: =WORKDAY(K15-1, L15+M15, IndHolidays) -> 46139 | Q15: =WORKDAY(K15-1, L15+M15, IndHolidays) -> 46139 | R15: Completed | S15: Completed Dev testing; Connected with QE to test from local (completed) | T15: 3 | U15: =WORKDAY(Q15, T15, IndHolidays) -> 46142 | V15: 1.5 | W15: =WORKDAY(U15, V15, IndHolidays) -> 46146 | X15: =WORKDAY(W15,0, IndHolidays) -> 46146 | Y15: 3 | Z15: =WORKDAY(X15, Y15, IndHolidays) -> 46149 | AA15: =WORKDAY(Z15, 0, IndHolidays) -> 46149 | AB15: =WORKDAY(AA15, 0, IndHolidays) -> 46149 | AC15: =WORKDAY(AB15, 1, IndHolidays) -> 46150 | AD15: =WORKDAY(AC15, 0, IndHolidays) -> 46150 | AF15: =WORKDAY(AD15, AE15, IndHolidays) -> 46150 | AG15: 2 | AH15: =WORKDAY(AF15, AG15, IndHolidays) -> 46154 | AI15: 3 | AJ15: =WORKDAY(AH15, AI15, IndHolidays) -> 46157 | AK15: =WORKDAY(AJ15, 0, IndHolidays) -> 46157 | AL15: =WORKDAY(AK15, 1, IndHolidays) -> 46160 | AM15: =WORKDAY(AL15, 0, IndHolidays) -> 46160 | AO15: =WORKDAY(AM15, AN15, IndHolidays) -> 46160 | AP15: =AO15 -> 46160 | AQ15: =AP15 -> 46160 | AR15: =WORKDAY(AQ15, 1, IndHolidays) -> 46161 | AT15: =WORKDAY(AR15, AS15, IndHolidays) -> 46161 | AU15: 0 | AV15: =WORKDAY(AT15, AU15, IndHolidays) -> 46161 | AW15: 0 | AX15: =WORKDAY(AV15, AW15, IndHolidays) -> 46161 | AY15: =_xlfn.MINIFS(ReleaseTimeline!$A$2:$A$27, ReleaseTimeline!$A$2:$A$27, ">="&(MAX(AX15,AO15))) -> 46163 | AZ15: =VLOOKUP(AY15,ReleaseTimeline!$A$1:$E$27,2,FALSE) -> Release 11 | BA15: =WORKDAY(AZ15, 3, IndHolidays) -> #VALUE! | BB15: =VLOOKUP(AZ15,ReleaseTimeline!$B$2:$C$27,2,FALSE) -> 46170 | BC15: =WORKDAY(BB15, -5) -> 46163 | BD15: =(BB15 - P15) -> 31 | BF15: =(T15+Y15+AI15+AW15) -> 9
A16: 15 | B16: Assessments | C16: =VLOOKUP(B16,'Target Tech'!$C$7:$J$33,8,FALSE) -> Complete ASP | D16: Yes | E16: 0 | F16: 46141 | G16: 46149 | H16: page_10 | I16: Pod 3 | K16: 46149 | L16: 3 | M16: 0 | N16: 10 | O16: =WORKDAY(K16-1, L16+M16, IndHolidays) -> 46153 | P16: =WORKDAY(K16-1, L16+M16, IndHolidays) -> 46153 | Q16: =WORKDAY(K16-1, L16+M16, IndHolidays) -> 46153 | T16: 3 | U16: =WORKDAY(Q16, T16, IndHolidays) -> 46156 | V16: 1.5 | W16: =WORKDAY(U16, V16, IndHolidays) -> 46157 | X16: =WORKDAY(W16,0, IndHolidays) -> 46157 | Y16: 3 | Z16: =WORKDAY(X16, Y16, IndHolidays) -> 46162 | AA16: =WORKDAY(Z16, 0, IndHolidays) -> 46162 | AB16: =WORKDAY(AA16, 0, IndHolidays) -> 46162 | AC16: =WORKDAY(AB16, 1, IndHolidays) -> 46163 | AD16: =WORKDAY(AC16, 0, IndHolidays) -> 46163 | AE16: 3 | AF16: =WORKDAY(AD16, AE16, IndHolidays) -> 46168 | AG16: 2 | AH16: =WORKDAY(AF16, AG16, IndHolidays) -> 46171 | AI16: 3 | AJ16: =WORKDAY(AH16, AI16, IndHolidays) -> 46177 | AK16: =WORKDAY(AJ16, 0, IndHolidays) -> 46177 | AL16: =WORKDAY(AK16, 1, IndHolidays) -> 46178 | AM16: =WORKDAY(AL16, 0, IndHolidays) -> 46178 | AN16: 1 | AO16: =WORKDAY(AM16, AN16, IndHolidays) -> 46181 | AP16: =AO16 -> 46181 | AQ16: =AP16 -> 46181 | AR16: =WORKDAY(AQ16, 1, IndHolidays) -> 46182 | AS16: 3 | AT16: =WORKDAY(AR16, AS16, IndHolidays) -> 46185 | AU16: 0 | AV16: =WORKDAY(AT16, AU16, IndHolidays) -> 46185 | AW16: 0 | AX16: =WORKDAY(AV16, AW16, IndHolidays) -> 46185 | AY16: =_xlfn.MINIFS(ReleaseTimeline!$A$2:$A$27, ReleaseTimeline!$A$2:$A$27, ">="&(MAX(AX16,AO16))) -> 46191 | AZ16: =VLOOKUP(AY16,ReleaseTimeline!$A$1:$E$27,2,FALSE) -> Release 13 | BA16: =WORKDAY(AZ16, 3, IndHolidays) -> #VALUE! | BB16: =VLOOKUP(AZ16,ReleaseTimeline!$B$2:$C$27,2,FALSE) -> 46198 | BC16: =WORKDAY(BB16, -5) -> 46191 | BD16: =(BB16 - P16) -> 45 | BF16: =(T16+Y16+AI16+AW16) -> 9
A17: 16 | B17: AssetAware | C17: =VLOOKUP(B17,'Target Tech'!$C$7:$J$33,8,FALSE) -> Complete ASP | D17: No | E17: 2 | F17: 46136 | G17: 46134 | H17: expressAssetHistory.aspx | I17: Pod 3 | J17: Mizan | K17: 46135 | L17: 3 | M17: 0 | N17: 1 | O17: =WORKDAY(K17-1, L17+M17, IndHolidays) -> 46139 | P17: =WORKDAY(K17-1, L17+M17, IndHolidays) -> 46139 | Q17: =WORKDAY(K17-1, L17+M17, IndHolidays) -> 46139 | S17: Dev completed and test case in creation | T17: 3 | U17: =WORKDAY(Q17, T17, IndHolidays) -> 46142 | V17: 1.5 | W17: =WORKDAY(U17, V17, IndHolidays) -> 46146 | X17: =WORKDAY(W17,0, IndHolidays) -> 46146 | Y17: 3 | Z17: =WORKDAY(X17, Y17, IndHolidays) -> 46149 | AA17: =WORKDAY(Z17, 0, IndHolidays) -> 46149 | AB17: =WORKDAY(AA17, 0, IndHolidays) -> 46149 | AC17: =WORKDAY(AB17, 1, IndHolidays) -> 46150 | AD17: =WORKDAY(AC17, 0, IndHolidays) -> 46150 | AF17: =WORKDAY(AD17, AE17, IndHolidays) -> 46150 | AG17: 2 | AH17: =WORKDAY(AF17, AG17, IndHolidays) -> 46154 | AI17: 3 | AJ17: =WORKDAY(AH17, AI17, IndHolidays) -> 46157 | AK17: =WORKDAY(AJ17, 0, IndHolidays) -> 46157 | AL17: =WORKDAY(AK17, 1, IndHolidays) -> 46160 | AM17: =WORKDAY(AL17, 0, IndHolidays) -> 46160 | AO17: =WORKDAY(AM17, AN17, IndHolidays) -> 46160 | AP17: =AO17 -> 46160 | AQ17: =AP17 -> 46160 | AR17: =WORKDAY(AQ17, 1, IndHolidays) -> 46161 | AT17: =WORKDAY(AR17, AS17, IndHolidays) -> 46161 | AU17: 0 | AV17: =WORKDAY(AT17, AU17, IndHolidays) -> 46161 | AW17: 0 | AX17: =WORKDAY(AV17, AW17, IndHolidays) -> 46161 | AY17: =_xlfn.MINIFS(ReleaseTimeline!$A$2:$A$27, ReleaseTimeline!$A$2:$A$27, ">="&(MAX(AX17,AO17))) -> 46163 | AZ17: =VLOOKUP(AY17,ReleaseTimeline!$A$1:$E$27,2,FALSE) -> Release 11 | BA17: =WORKDAY(AZ17, 3, IndHolidays) -> #VALUE! | BB17: =VLOOKUP(AZ17,ReleaseTimeline!$B$2:$C$27,2,FALSE) -> 46170 | BC17: =WORKDAY(BB17, -5) -> 46163 | BD17: =(BB17 - P17) -> 31 | BF17: =(T17+Y17+AI17+AW17) -> 9
A18: 17 | B18: AssetAware | C18: =VLOOKUP(B18,'Target Tech'!$C$7:$J$33,8,FALSE) -> Complete ASP | D18: No | E18: 2 | F18: 46136 | G18: 46134 | H18: assetvendors.aspx | I18: Pod 3 | J18: swarneem | K18: 46135 | L18: 3 | M18: 0 | N18: 2 | O18: =WORKDAY(K18-1, L18+M18, IndHolidays) -> 46139 | P18: =WORKDAY(K18-1, L18+M18, IndHolidays) -> 46139 | Q18: =WORKDAY(K18-1, L18+M18, IndHolidays) -> 46139 | S18: Dev in Progress as swarneem working on addressbook bugs and raised PR, however ETA to raise PR is on 28 APR | T18: 3 | U18: =WORKDAY(Q18, T18, IndHolidays) -> 46142 | V18: 1.5 | W18: =WORKDAY(U18, V18, IndHolidays) -> 46146 | X18: =WORKDAY(W18,0, IndHolidays) -> 46146 | Y18: 3 | Z18: =WORKDAY(X18, Y18, IndHolidays) -> 46149 | AA18: =WORKDAY(Z18, 0, IndHolidays) -> 46149 | AB18: =WORKDAY(AA18, 0, IndHolidays) -> 46149 | AC18: =WORKDAY(AB18, 1, IndHolidays) -> 46150 | AD18: =WORKDAY(AC18, 0, IndHolidays) -> 46150 | AF18: =WORKDAY(AD18, AE18, IndHolidays) -> 46150 | AG18: 2 | AH18: =WORKDAY(AF18, AG18, IndHolidays) -> 46154 | AI18: 3 | AJ18: =WORKDAY(AH18, AI18, IndHolidays) -> 46157 | AK18: =WORKDAY(AJ18, 0, IndHolidays) -> 46157 | AL18: =WORKDAY(AK18, 1, IndHolidays) -> 46160 | AM18: =WORKDAY(AL18, 0, IndHolidays) -> 46160 | AO18: =WORKDAY(AM18, AN18, IndHolidays) -> 46160 | AP18: =AO18 -> 46160 | AQ18: =AP18 -> 46160 | AR18: =WORKDAY(AQ18, 1, IndHolidays) -> 46161 | AT18: =WORKDAY(AR18, AS18, IndHolidays) -> 46161 | AU18: 0 | AV18: =WORKDAY(AT18, AU18, IndHolidays) -> 46161 | AW18: 0 | AX18: =WORKDAY(AV18, AW18, IndHolidays) -> 46161 | AY18: =_xlfn.MINIFS(ReleaseTimeline!$A$2:$A$27, ReleaseTimeline!$A$2:$A$27, ">="&(MAX(AX18,AO18))) -> 46163 | AZ18: =VLOOKUP(AY18,ReleaseTimeline!$A$1:$E$27,2,FALSE) -> Release 11 | BA18: =WORKDAY(AZ18, 3, IndHolidays) -> #VALUE! | BB18: =VLOOKUP(AZ18,ReleaseTimeline!$B$2:$C$27,2,FALSE) -> 46170 | BC18: =WORKDAY(BB18, -5) -> 46163 | BD18: =(BB18 - P18) -> 31 | BF18: =(T18+Y18+AI18+AW18) -> 9
A19: 18 | B19: AssetAware | C19: =VLOOKUP(B19,'Target Tech'!$C$7:$J$33,8,FALSE) -> Complete ASP | D19: No | E19: 2 | F19: 46136 | G19: 46134 | H19: assets.aspx | I19: Pod 3 | J19: Mizan | K19: 46135 | L19: 3 | M19: 0 | N19: 3 | O19: =WORKDAY(K19-1, L19+M19, IndHolidays) -> 46139 | P19: =WORKDAY(K19-1, L19+M19, IndHolidays) -> 46139 | Q19: =WORKDAY(K19-1, L19+M19, IndHolidays) -> 46139 | S19: Dev completed and test case in creation | T19: 3 | U19: =WORKDAY(Q19, T19, IndHolidays) -> 46142 | V19: 1.5 | W19: =WORKDAY(U19, V19, IndHolidays) -> 46146 | X19: =WORKDAY(W19,0, IndHolidays) -> 46146 | Y19: 3 | Z19: =WORKDAY(X19, Y19, IndHolidays) -> 46149 | AA19: =WORKDAY(Z19, 0, IndHolidays) -> 46149 | AB19: =WORKDAY(AA19, 0, IndHolidays) -> 46149 | AC19: =WORKDAY(AB19, 1, IndHolidays) -> 46150 | AD19: =WORKDAY(AC19, 0, IndHolidays) -> 46150 | AF19: =WORKDAY(AD19, AE19, IndHolidays) -> 46150 | AG19: 2 | AH19: =WORKDAY(AF19, AG19, IndHolidays) -> 46154 | AI19: 3 | AJ19: =WORKDAY(AH19, AI19, IndHolidays) -> 46157 | AK19: =WORKDAY(AJ19, 0, IndHolidays) -> 46157 | AL19: =WORKDAY(AK19, 1, IndHolidays) -> 46160 | AM19: =WORKDAY(AL19, 0, IndHolidays) -> 46160 | AO19: =WORKDAY(AM19, AN19, IndHolidays) -> 46160 | AP19: =AO19 -> 46160 | AQ19: =AP19 -> 46160 | AR19: =WORKDAY(AQ19, 1, IndHolidays) -> 46161 | AT19: =WORKDAY(AR19, AS19, IndHolidays) -> 46161 | AU19: 0 | AV19: =WORKDAY(AT19, AU19, IndHolidays) -> 46161 | AW19: 0 | AX19: =WORKDAY(AV19, AW19, IndHolidays) -> 46161 | AY19: =_xlfn.MINIFS(ReleaseTimeline!$A$2:$A$27, ReleaseTimeline!$A$2:$A$27, ">="&(MAX(AX19,AO19))) -> 46163 | AZ19: =VLOOKUP(AY19,ReleaseTimeline!$A$1:$E$27,2,FALSE) -> Release 11 | BA19: =WORKDAY(AZ19, 3, IndHolidays) -> #VALUE! | BB19: =VLOOKUP(AZ19,ReleaseTimeline!$B$2:$C$27,2,FALSE) -> 46170 | BC19: =WORKDAY(BB19, -5) -> 46163 | BD19: =(BB19 - P19) -> 31 | BF19: =(T19+Y19+AI19+AW19) -> 9
A20: 19 | B20: AssetAware | C20: =VLOOKUP(B20,'Target Tech'!$C$7:$J$33,8,FALSE) -> Complete ASP | D20: No | E20: 2 | F20: 46136 | G20: 46134 | H20: assetwarrantlytypes.aspx | I20: Pod 3 | J20: swarneem | K20: 46135 | L20: 3 | M20: 0 | N20: 4 | O20: =WORKDAY(K20-1, L20+M20, IndHolidays) -> 46139 | P20: =WORKDAY(K20-1, L20+M20, IndHolidays) -> 46139 | Q20: =WORKDAY(K20-1, L20+M20, IndHolidays) -> 46139 | S20: Dev in Progress as swarneem working on addressbook bugs and raised PR, however ETA to raise PR is on | T20: 3 | U20: =WORKDAY(Q20, T20, IndHolidays) -> 46142 | V20: 1.5 | W20: =WORKDAY(U20, V20, IndHolidays) -> 46146 | X20: =WORKDAY(W20,0, IndHolidays) -> 46146 | Y20: 3 | Z20: =WORKDAY(X20, Y20, IndHolidays) -> 46149 | AA20: =WORKDAY(Z20, 0, IndHolidays) -> 46149 | AB20: =WORKDAY(AA20, 0, IndHolidays) -> 46149 | AC20: =WORKDAY(AB20, 1, IndHolidays) -> 46150 | AD20: =WORKDAY(AC20, 0, IndHolidays) -> 46150 | AE20: 3 | AF20: =WORKDAY(AD20, AE20, IndHolidays) -> 46155 | AG20: 2 | AH20: =WORKDAY(AF20, AG20, IndHolidays) -> 46157 | AI20: 3 | AJ20: =WORKDAY(AH20, AI20, IndHolidays) -> 46162 | AK20: =WORKDAY(AJ20, 0, IndHolidays) -> 46162 | AL20: =WORKDAY(AK20, 1, IndHolidays) -> 46163 | AM20: =WORKDAY(AL20, 0, IndHolidays) -> 46163 | AN20: 1 | AO20: =WORKDAY(AM20, AN20, IndHolidays) -> 46164 | AP20: =AO20 -> 46164 | AQ20: =AP20 -> 46164 | AR20: =WORKDAY(AQ20, 1, IndHolidays) -> 46167 | AS20: 3 | AT20: =WORKDAY(AR20, AS20, IndHolidays) -> 46171 | AU20: 0 | AV20: =WORKDAY(AT20, AU20, IndHolidays) -> 46171 | AW20: 0 | AX20: =WORKDAY(AV20, AW20, IndHolidays) -> 46171 | AY20: =_xlfn.MINIFS(ReleaseTimeline!$A$2:$A$27, ReleaseTimeline!$A$2:$A$27, ">="&(MAX(AX20,AO20))) -> 46177 | AZ20: =VLOOKUP(AY20,ReleaseTimeline!$A$1:$E$27,2,FALSE) -> Release 12 | BA20: =WORKDAY(AZ20, 3, IndHolidays) -> #VALUE! | BB20: =VLOOKUP(AZ20,ReleaseTimeline!$B$2:$C$27,2,FALSE) -> 46184 | BC20: =WORKDAY(BB20, -5) -> 46177 | BD20: =(BB20 - P20) -> 45 | BF20: =(T20+Y20+AI20+AW20) -> 9
A21: 20 | B21: AssetAware | C21: =VLOOKUP(B21,'Target Tech'!$C$7:$J$33,8,FALSE) -> Complete ASP | D21: No | E21: 2 | F21: 46136 | G21: 46134 | H21: assetLeases.aspx | I21: Pod 3 | J21: Mizan | K21: 46140 | L21: 3 | M21: 0 | N21: 5 | O21: =WORKDAY(K21-1, L21+M21, IndHolidays) -> 46142 | P21: =WORKDAY(K21-1, L21+M21, IndHolidays) -> 46142 | Q21: =WORKDAY(K21-1, L21+M21, IndHolidays) -> 46142 | S21: Dev in Progress as swarneem working on addressbook bugs and raised PR, however ETA to raise PR is on | T21: 3 | U21: =WORKDAY(Q21, T21, IndHolidays) -> 46148 | V21: 1.5 | W21: =WORKDAY(U21, V21, IndHolidays) -> 46149 | X21: =WORKDAY(W21,0, IndHolidays) -> 46149 | Y21: 3 | Z21: =WORKDAY(X21, Y21, IndHolidays) -> 46154 | AA21: =WORKDAY(Z21, 0, IndHolidays) -> 46154 | AB21: =WORKDAY(AA21, 0, IndHolidays) -> 46154 | AC21: =WORKDAY(AB21, 1, IndHolidays) -> 46155 | AD21: =WORKDAY(AC21, 0, IndHolidays) -> 46155 | AE21: 3 | AF21: =WORKDAY(AD21, AE21, IndHolidays) -> 46160 | AG21: 2 | AH21: =WORKDAY(AF21, AG21, IndHolidays) -> 46162 | AI21: 3 | AJ21: =WORKDAY(AH21, AI21, IndHolidays) -> 46167 | AK21: =WORKDAY(AJ21, 0, IndHolidays) -> 46167 | AL21: =WORKDAY(AK21, 1, IndHolidays) -> 46168 | AM21: =WORKDAY(AL21, 0, IndHolidays) -> 46168 | AN21: 1 | AO21: =WORKDAY(AM21, AN21, IndHolidays) -> 46169 | AP21: =AO21 -> 46169 | AQ21: =AP21 -> 46169 | AR21: =WORKDAY(AQ21, 1, IndHolidays) -> 46171 | AS21: 3 | AT21: =WORKDAY(AR21, AS21, IndHolidays) -> 46177 | AU21: 0 | AV21: =WORKDAY(AT21, AU21, IndHolidays) -> 46177 | AW21: 0 | AX21: =WORKDAY(AV21, AW21, IndHolidays) -> 46177 | AY21: =_xlfn.MINIFS(ReleaseTimeline!$A$2:$A$27, ReleaseTimeline!$A$2:$A$27, ">="&(MAX(AX21,AO21))) -> 46177 | AZ21: =VLOOKUP(AY21,ReleaseTimeline!$A$1:$E$27,2,FALSE) -> Release 12 | BA21: =WORKDAY(AZ21, 3, IndHolidays) -> #VALUE! | BB21: =VLOOKUP(AZ21,ReleaseTimeline!$B$2:$C$27,2,FALSE) -> 46184 | BC21: =WORKDAY(BB21, -5) -> 46177 | BD21: =(BB21 - P21) -> 42 | BF21: =(T21+Y21+AI21+AW21) -> 9
A22: 21 | B22: AssetAware | C22: =VLOOKUP(B22,'Target Tech'!$C$7:$J$33,8,FALSE) -> Complete ASP | D22: No | E22: 2 | F22: 46136 | G22: 46146 | H22: assetHistory.aspx | I22: Pod 3 | J22: Mizan | K22: 46146 | L22: 3 | M22: 0 | N22: 6 | O22: =WORKDAY(K22-1, L22+M22, IndHolidays) -> 46148 | P22: =WORKDAY(K22-1, L22+M22, IndHolidays) -> 46148 | Q22: 46148 | T22: =WORKDAY(P22, S22, IndHolidays) -> 46148 | U22: 1.5 | V22: =WORKDAY(T22, U22, IndHolidays) -> 46149 | W22: =WORKDAY(V22,0, IndHolidays) -> 46149 | X22: 3 | Y22: =WORKDAY(W22, X22, IndHolidays) -> 46154 | Z22: =WORKDAY(Y22, 0, IndHolidays) -> 46154 | AA22: =WORKDAY(Z22, 0, IndHolidays) -> 46154 | AB22: =WORKDAY(AA22, 1, IndHolidays) -> 46155 | AC22: =WORKDAY(AB22, 0, IndHolidays) -> 46155 | AD22: 3 | AE22: =WORKDAY(AC22, AD22, IndHolidays) -> 46160 | AF22: 2 | AG22: =WORKDAY(AE22, AF22, IndHolidays) -> 46162 | AH22: 3 | AI22: =WORKDAY(AG22, AH22, IndHolidays) -> 46167 | AJ22: =WORKDAY(AI22, 0, IndHolidays) -> 46167 | AK22: =WORKDAY(AJ22, 1, IndHolidays) -> 46168 | AL22: =WORKDAY(AK22, 0, IndHolidays) -> 46168 | AM22: 1 | AN22: =WORKDAY(AL22, AM22, IndHolidays) -> 46169 | AO22: =AN22 -> 46169 | AP22: =AO22 -> 46169 | AQ22: =WORKDAY(AP22, 1, IndHolidays) -> 46171 | AR22: 3 | AS22: =WORKDAY(AQ22, AR22, IndHolidays) -> 46177 | AT22: 0 | AU22: =WORKDAY(AS22, AT22, IndHolidays) -> 46177 | AV22: 0 | AW22: =WORKDAY(AU22, AV22, IndHolidays) -> 46177 | AX22: =_xlfn.MINIFS(ReleaseTimeline!$A$2:$A$27, ReleaseTimeline!$A$2:$A$27, ">="&(MAX(AW22,AN22))) -> 46177 | AY22: =VLOOKUP(AX22,ReleaseTimeline!$A$1:$E$27,2,FALSE) -> Release 12 | AZ22: =VLOOKUP(AX22,ReleaseTimeline!$B$2:$C$27,2,FALSE) -> #N/A | BA22: =(AY22 - M22) -> #VALUE! | BC22: =(Q22+V22+AF22+AT22) -> 92299
A23: 21 | B23: AssetAware | C23: =VLOOKUP(B23,'Target Tech'!$C$7:$J$33,8,FALSE) -> Complete ASP | D23: No | E23: 2 | F23: 46136 | G23: 46147 | H23: assetVendorAddressContact.aspx | I23: Pod 3 | J23: Mizan | K23: 46147 | L23: 3 | M23: 0 | N23: 7 | O23: 46150 | P23: 46150 | Q23: 46150 | S23: =WORKDAY(O23, R23, IndHolidays) -> 46150 | T23: 1.5 | U23: =WORKDAY(S23, T23, IndHolidays) -> 46153 | V23: =WORKDAY(U23,0, IndHolidays) -> 46153 | W23: 3 | X23: =WORKDAY(V23, W23, IndHolidays) -> 46156 | Y23: =WORKDAY(X23, 0, IndHolidays) -> 46156 | Z23: =WORKDAY(Y23, 0, IndHolidays) -> 46156 | AA23: =WORKDAY(Z23, 1, IndHolidays) -> 46157 | AB23: =WORKDAY(AA23, 0, IndHolidays) -> 46157 | AC23: 3 | AD23: =WORKDAY(AB23, AC23, IndHolidays) -> 46162 | AE23: 2 | AF23: =WORKDAY(AD23, AE23, IndHolidays) -> 46164 | AG23: 3 | AH23: =WORKDAY(AF23, AG23, IndHolidays) -> 46169 | AI23: =WORKDAY(AH23, 0, IndHolidays) -> 46169 | AJ23: =WORKDAY(AI23, 1, IndHolidays) -> 46171 | AK23: =WORKDAY(AJ23, 0, IndHolidays) -> 46171 | AL23: 1 | AM23: =WORKDAY(AK23, AL23, IndHolidays) -> 46174 | AN23: =AM23 -> 46174 | AO23: =AN23 -> 46174 | AP23: =WORKDAY(AO23, 1, IndHolidays) -> 46176 | AQ23: 3 | AR23: =WORKDAY(AP23, AQ23, IndHolidays) -> 46181 | AS23: 0 | AT23: =WORKDAY(AR23, AS23, IndHolidays) -> 46181 | AU23: 0 | AV23: =WORKDAY(AT23, AU23, IndHolidays) -> 46181 | AW23: =_xlfn.MINIFS(ReleaseTimeline!$A$2:$A$27, ReleaseTimeline!$A$2:$A$27, ">="&(MAX(AV23,AM23))) -> 46191 | AX23: =VLOOKUP(AW23,ReleaseTimeline!$A$1:$E$27,2,FALSE) -> Release 13 | AY23: =VLOOKUP(AW23,ReleaseTimeline!$B$2:$C$27,2,FALSE) -> #N/A
A24: 21 | B24: AssetAware | C24: =VLOOKUP(B24,'Target Tech'!$C$7:$J$33,8,FALSE) -> Complete ASP | D24: No | E24: 2 | F24: 46136 | G24: 46147 | H24: assetvendor.aspx | I24: Pod 3 | J24: Mizan | K24: 46147 | L24: 3 | M24: 0 | N24: 8 | O24: 46150 | P24: 46150 | Q24: 46150 | S24: =WORKDAY(O24, R24, IndHolidays) -> 46150 | T24: 1.5 | U24: =WORKDAY(S24, T24, IndHolidays) -> 46153 | V24: =WORKDAY(U24,0, IndHolidays) -> 46153 | W24: 3 | X24: =WORKDAY(V24, W24, IndHolidays) -> 46156 | Y24: =WORKDAY(X24, 0, IndHolidays) -> 46156 | Z24: =WORKDAY(Y24, 0, IndHolidays) -> 46156 | AA24: =WORKDAY(Z24, 1, IndHolidays) -> 46157 | AB24: =WORKDAY(AA24, 0, IndHolidays) -> 46157 | AC24: 3 | AD24: =WORKDAY(AB24, AC24, IndHolidays) -> 46162 | AE24: 2 | AF24: =WORKDAY(AD24, AE24, IndHolidays) -> 46164 | AG24: 3 | AH24: =WORKDAY(AF24, AG24, IndHolidays) -> 46169 | AI24: =WORKDAY(AH24, 0, IndHolidays) -> 46169 | AJ24: =WORKDAY(AI24, 1, IndHolidays) -> 46171 | AK24: =WORKDAY(AJ24, 0, IndHolidays) -> 46171 | AL24: 1 | AM24: =WORKDAY(AK24, AL24, IndHolidays) -> 46174 | AN24: =AM24 -> 46174 | AO24: =AN24 -> 46174 | AP24: =WORKDAY(AO24, 1, IndHolidays) -> 46176 | AQ24: 3 | AR24: =WORKDAY(AP24, AQ24, IndHolidays) -> 46181 | AS24: 0 | AT24: =WORKDAY(AR24, AS24, IndHolidays) -> 46181 | AU24: 0 | AV24: =WORKDAY(AT24, AU24, IndHolidays) -> 46181 | AW24: =_xlfn.MINIFS(ReleaseTimeline!$A$2:$A$27, ReleaseTimeline!$A$2:$A$27, ">="&(MAX(AV24,AM24))) -> 46191 | AX24: =VLOOKUP(AW24,ReleaseTimeline!$A$1:$E$27,2,FALSE) -> Release 13 | AY24: =VLOOKUP(AW24,ReleaseTimeline!$B$2:$C$27,2,FALSE) -> #N/A
A25: 20 | B25: Communication | C25: =VLOOKUP(B25,'Target Tech'!$C$7:$J$33,8,FALSE) -> Complete ASP | D25: No | E25: 2 | F25: 46147 | G25: 46147 | H25: page_1 | I25: Pod 2 | J25: Pod 2_Member1 | K25: =WORKDAY(F25,E25) -> 46149 | L25: 3 | M25: 0 | N25: 1 | O25: =WORKDAY(K25-1, L25+M25, IndHolidays) -> 46153 | P25: =WORKDAY(K25-1, L25+M25, IndHolidays) -> 46153 | Q25: =WORKDAY(K25-1, L25+M25, IndHolidays) -> 46153 | T25: 3 | U25: =WORKDAY(Q25, T25, IndHolidays) -> 46156 | V25: 1.5 | W25: =WORKDAY(U25, V25, IndHolidays) -> 46157 | X25: =WORKDAY(W25,0, IndHolidays) -> 46157 | Y25: 3 | Z25: =WORKDAY(X25, Y25, IndHolidays) -> 46162 | AA25: =WORKDAY(Z25, 0, IndHolidays) -> 46162 | AB25: =WORKDAY(AA25, 0, IndHolidays) -> 46162 | AC25: =WORKDAY(AB25, 1, IndHolidays) -> 46163 | AD25: =WORKDAY(AC25, 0, IndHolidays) -> 46163 | AF25: =WORKDAY(AD25, AE25, IndHolidays) -> 46163 | AG25: 2 | AH25: =WORKDAY(AF25, AG25, IndHolidays) -> 46167 | AI25: 3 | AJ25: =WORKDAY(AH25, AI25, IndHolidays) -> 46171 | AK25: =WORKDAY(AJ25, 0, IndHolidays) -> 46171 | AL25: =WORKDAY(AK25, 1, IndHolidays) -> 46174 | AM25: =WORKDAY(AL25, 0, IndHolidays) -> 46174 | AO25: =WORKDAY(AM25, AN25, IndHolidays) -> 46174 | AP25: =AO25 -> 46174 | AQ25: =AP25 -> 46174 | AR25: =WORKDAY(AQ25, 1, IndHolidays) -> 46176 | AT25: =WORKDAY(AR25, AS25, IndHolidays) -> 46176 | AU25: 0 | AV25: =WORKDAY(AT25, AU25, IndHolidays) -> 46176 | AW25: 0 | AX25: =WORKDAY(AV25, AW25, IndHolidays) -> 46176 | AY25: =_xlfn.MINIFS(ReleaseTimeline!$A$2:$A$27, ReleaseTimeline!$A$2:$A$27, ">="&(MAX(AX25,AO25))) -> 46177 | AZ25: =VLOOKUP(AY25,ReleaseTimeline!$A$1:$E$27,2,FALSE) -> Release 12 | BA25: =WORKDAY(AZ25, 3, IndHolidays) -> #VALUE! | BB25: =VLOOKUP(AZ25,ReleaseTimeline!$B$2:$C$27,2,FALSE) -> 46184 | BC25: =WORKDAY(BB25, -5) -> 46177 | BD25: =(BB25 - P25) -> 31 | BF25: =(T25+Y25+AI25+AW25) -> 9
A26: 21 | B26: Communication | C26: =VLOOKUP(B26,'Target Tech'!$C$7:$J$33,8,FALSE) -> Complete ASP | D26: No | E26: 2 | F26: 46141 | G26: 46141 | H26: page_2 | I26: Pod 2 | J26: Pod 2_Member2 | K26: =WORKDAY(F26,E26) -> 46143 | L26: 3 | M26: 0 | N26: 2 | O26: =WORKDAY(K26-1, L26+M26, IndHolidays) -> 46148 | P26: =WORKDAY(K26-1, L26+M26, IndHolidays) -> 46148 | Q26: =WORKDAY(K26-1, L26+M26, IndHolidays) -> 46148 | T26: 3 | U26: =WORKDAY(Q26, T26, IndHolidays) -> 46153 | V26: 1.5 | W26: =WORKDAY(U26, V26, IndHolidays) -> 46154 | X26: =WORKDAY(W26,0, IndHolidays) -> 46154 | Y26: 3 | Z26: =WORKDAY(X26, Y26, IndHolidays) -> 46157 | AA26: =WORKDAY(Z26, 0, IndHolidays) -> 46157 | AB26: =WORKDAY(AA26, 0, IndHolidays) -> 46157 | AC26: =WORKDAY(AB26, 1, IndHolidays) -> 46160 | AD26: =WORKDAY(AC26, 0, IndHolidays) -> 46160 | AF26: =WORKDAY(AD26, AE26, IndHolidays) -> 46160 | AG26: 2 | AH26: =WORKDAY(AF26, AG26, IndHolidays) -> 46162 | AI26: 3 | AJ26: =WORKDAY(AH26, AI26, IndHolidays) -> 46167 | AK26: =WORKDAY(AJ26, 0, IndHolidays) -> 46167 | AL26: =WORKDAY(AK26, 1, IndHolidays) -> 46168 | AM26: =WORKDAY(AL26, 0, IndHolidays) -> 46168 | AO26: =WORKDAY(AM26, AN26, IndHolidays) -> 46168 | AP26: =AO26 -> 46168 | AQ26: =AP26 -> 46168 | AR26: =WORKDAY(AQ26, 1, IndHolidays) -> 46169 | AT26: =WORKDAY(AR26, AS26, IndHolidays) -> 46169 | AU26: 0 | AV26: =WORKDAY(AT26, AU26, IndHolidays) -> 46169 | AW26: 0 | AX26: =WORKDAY(AV26, AW26, IndHolidays) -> 46169 | AY26: =_xlfn.MINIFS(ReleaseTimeline!$A$2:$A$27, ReleaseTimeline!$A$2:$A$27, ">="&(MAX(AX26,AO26))) -> 46177 | AZ26: =VLOOKUP(AY26,ReleaseTimeline!$A$1:$E$27,2,FALSE) -> Release 12 | BA26: =WORKDAY(AZ26, 3, IndHolidays) -> #VALUE! | BB26: =VLOOKUP(AZ26,ReleaseTimeline!$B$2:$C$27,2,FALSE) -> 46184 | BC26: =WORKDAY(BB26, -5) -> 46177 | BD26: =(BB26 - P26) -> 36 | BF26: =(T26+Y26+AI26+AW26) -> 9
A27: 22 | B27: Communication | C27: =VLOOKUP(B27,'Target Tech'!$C$7:$J$33,8,FALSE) -> Complete ASP | D27: No | E27: 2 | F27: 46141 | G27: 46141 | H27: page_3 | I27: Pod 2 | J27: Pod 2_Member3 | K27: =WORKDAY(F27,E27) -> 46143 | L27: 3 | M27: 0 | N27: 3 | O27: =WORKDAY(K27-1, L27+M27, IndHolidays) -> 46148 | P27: =WORKDAY(K27-1, L27+M27, IndHolidays) -> 46148 | Q27: =WORKDAY(K27-1, L27+M27, IndHolidays) -> 46148 | T27: 3 | U27: =WORKDAY(Q27, T27, IndHolidays) -> 46153 | V27: 1.5 | W27: =WORKDAY(U27, V27, IndHolidays) -> 46154 | X27: =WORKDAY(W27,0, IndHolidays) -> 46154 | Y27: 3 | Z27: =WORKDAY(X27, Y27, IndHolidays) -> 46157 | AA27: =WORKDAY(Z27, 0, IndHolidays) -> 46157 | AB27: =WORKDAY(AA27, 0, IndHolidays) -> 46157 | AC27: =WORKDAY(AB27, 1, IndHolidays) -> 46160 | AD27: =WORKDAY(AC27, 0, IndHolidays) -> 46160 | AF27: =WORKDAY(AD27, AE27, IndHolidays) -> 46160 | AG27: 2 | AH27: =WORKDAY(AF27, AG27, IndHolidays) -> 46162 | AI27: 3 | AJ27: =WORKDAY(AH27, AI27, IndHolidays) -> 46167 | AK27: =WORKDAY(AJ27, 0, IndHolidays) -> 46167 | AL27: =WORKDAY(AK27, 1, IndHolidays) -> 46168 | AM27: =WORKDAY(AL27, 0, IndHolidays) -> 46168 | AO27: =WORKDAY(AM27, AN27, IndHolidays) -> 46168 | AP27: =AO27 -> 46168 | AQ27: =AP27 -> 46168 | AR27: =WORKDAY(AQ27, 1, IndHolidays) -> 46169 | AT27: =WORKDAY(AR27, AS27, IndHolidays) -> 46169 | AU27: 0 | AV27: =WORKDAY(AT27, AU27, IndHolidays) -> 46169 | AW27: 0 | AX27: =WORKDAY(AV27, AW27, IndHolidays) -> 46169 | AY27: =_xlfn.MINIFS(ReleaseTimeline!$A$2:$A$27, ReleaseTimeline!$A$2:$A$27, ">="&(MAX(AX27,AO27))) -> 46177 | AZ27: =VLOOKUP(AY27,ReleaseTimeline!$A$1:$E$27,2,FALSE) -> Release 12 | BA27: =WORKDAY(AZ27, 3, IndHolidays) -> #VALUE! | BB27: =VLOOKUP(AZ27,ReleaseTimeline!$B$2:$C$27,2,FALSE) -> 46184 | BC27: =WORKDAY(BB27, -5) -> 46177 | BD27: =(BB27 - P27) -> 36 | BF27: =(T27+Y27+AI27+AW27) -> 9
A28: 23 | B28: Communication | C28: =VLOOKUP(B28,'Target Tech'!$C$7:$J$33,8,FALSE) -> Complete ASP | D28: No | E28: 2 | F28: =WORKDAY(Q25,1) -> 46154 | G28: =WORKDAY(R25,1) -> 2 | H28: page_4 | I28: Pod 2 | J28: Pod 2_Member1 | K28: =WORKDAY(F28,E28) -> 46156 | L28: 3 | M28: 0 | N28: 4 | O28: =WORKDAY(K28-1, L28+M28, IndHolidays) -> 46160 | P28: =WORKDAY(K28-1, L28+M28, IndHolidays) -> 46160 | Q28: =WORKDAY(K28-1, L28+M28, IndHolidays) -> 46160 | T28: 3 | U28: =WORKDAY(Q28, T28, IndHolidays) -> 46163 | V28: 1.5 | W28: =WORKDAY(U28, V28, IndHolidays) -> 46164 | X28: =WORKDAY(W28,0, IndHolidays) -> 46164 | Y28: 3 | Z28: =WORKDAY(X28, Y28, IndHolidays) -> 46169 | AA28: =WORKDAY(Z28, 0, IndHolidays) -> 46169 | AB28: =WORKDAY(AA28, 0, IndHolidays) -> 46169 | AC28: =WORKDAY(AB28, 1, IndHolidays) -> 46171 | AD28: =WORKDAY(AC28, 0, IndHolidays) -> 46171 | AE28: 3 | AF28: =WORKDAY(AD28, AE28, IndHolidays) -> 46177 | AG28: 2 | AH28: =WORKDAY(AF28, AG28, IndHolidays) -> 46181 | AI28: 3 | AJ28: =WORKDAY(AH28, AI28, IndHolidays) -> 46184 | AK28: =WORKDAY(AJ28, 0, IndHolidays) -> 46184 | AL28: =WORKDAY(AK28, 1, IndHolidays) -> 46185 | AM28: =WORKDAY(AL28, 0, IndHolidays) -> 46185 | AN28: 1 | AO28: =WORKDAY(AM28, AN28, IndHolidays) -> 46188 | AP28: =AO28 -> 46188 | AQ28: =AP28 -> 46188 | AR28: =WORKDAY(AQ28, 1, IndHolidays) -> 46189 | AS28: 3 | AT28: =WORKDAY(AR28, AS28, IndHolidays) -> 46192 | AU28: 0 | AV28: =WORKDAY(AT28, AU28, IndHolidays) -> 46192 | AW28: 0 | AX28: =WORKDAY(AV28, AW28, IndHolidays) -> 46192 | AY28: =_xlfn.MINIFS(ReleaseTimeline!$A$2:$A$27, ReleaseTimeline!$A$2:$A$27, ">="&(MAX(AX28,AO28))) -> 46205 | AZ28: =VLOOKUP(AY28,ReleaseTimeline!$A$1:$E$27,2,FALSE) -> Release 14 | BA28: =WORKDAY(AZ28, 3, IndHolidays) -> #VALUE! | BB28: =VLOOKUP(AZ28,ReleaseTimeline!$B$2:$C$27,2,FALSE) -> 46212 | BC28: =WORKDAY(BB28, -5) -> 46205 | BD28: =(BB28 - P28) -> 52 | BE28: =(BB28-AZ28) -> #VALUE! | BF28: =(T28+Y28+AI28+AW28) -> 9 | BI28: =(BE28+BF28) -> #VALUE!
A29: 24 | B29: Content | F29: 46127 | G29: 46146 | H29: content\hyperlink.aspx | I29: Pod 3 | J29: Ramesh | K29: 46146 | L29: 3 | M29: 0 | N29: 8802 | O29: =WORKDAY(K29-1, L29+M29, IndHolidays) -> 46148 | P29: =WORKDAY(K29-1, L29+M29, IndHolidays) -> 46148 | Q29: =WORKDAY(K29-1, L29+M29, IndHolidays) -> 46148 | T29: 3 | U29: =WORKDAY(Q29, T29, IndHolidays) -> 46153 | V29: 1.5 | W29: =WORKDAY(U29, V29, IndHolidays) -> 46154 | X29: =WORKDAY(W29,0, IndHolidays) -> 46154 | Y29: 3 | Z29: =WORKDAY(X29, Y29, IndHolidays) -> 46157 | AA29: =WORKDAY(Z29, 0, IndHolidays) -> 46157 | AB29: =WORKDAY(AA29, 0, IndHolidays) -> 46157 | AC29: =WORKDAY(AB29, 1, IndHolidays) -> 46160 | AD29: =WORKDAY(AC29, 0, IndHolidays) -> 46160 | AF29: =WORKDAY(AD29, AE29, IndHolidays) -> 46160 | AG29: 2 | AH29: =WORKDAY(AF29, AG29, IndHolidays) -> 46162 | AI29: 3 | AJ29: =WORKDAY(AH29, AI29, IndHolidays) -> 46167 | AK29: =WORKDAY(AJ29, 0, IndHolidays) -> 46167 | AL29: =WORKDAY(AK29, 1, IndHolidays) -> 46168 | AM29: =WORKDAY(AL29, 0, IndHolidays) -> 46168 | AO29: =WORKDAY(AM29, AN29, IndHolidays) -> 46168 | AP29: =AO29 -> 46168 | AQ29: =AP29 -> 46168 | AR29: =WORKDAY(AQ29, 1, IndHolidays) -> 46169 | AT29: =WORKDAY(AR29, AS29, IndHolidays) -> 46169 | AU29: 0 | AV29: =WORKDAY(AT29, AU29, IndHolidays) -> 46169 | AW29: 0 | AX29: =WORKDAY(AV29, AW29, IndHolidays) -> 46169 | AY29: =_xlfn.MINIFS(ReleaseTimeline!$A$2:$A$27, ReleaseTimeline!$A$2:$A$27, ">="&(MAX(AX29,AO29))) -> 46177 | AZ29: =VLOOKUP(AY29,ReleaseTimeline!$A$1:$E$27,2,FALSE) -> Release 12 | BA29: =WORKDAY(AZ29, 3, IndHolidays) -> #VALUE! | BB29: =VLOOKUP(AZ29,ReleaseTimeline!$B$2:$C$27,2,FALSE) -> 46184 | BC29: =WORKDAY(BB29, -5) -> 46177 | BD29: =(BB29 - P29) -> 36 | BF29: =(T29+Y29+AI29+AW29) -> 9
A30: 25 | B30: Content | F30: 46127 | G30: 46146 | H30: content\sources\default.aspx.cs | I30: Pod 3 | J30: Amol | K30: 46146 | L30: 3 | M30: 0 | N30: 8801 | O30: =WORKDAY(K30-1, L30+M30, IndHolidays) -> 46148 | P30: =WORKDAY(K30-1, L30+M30, IndHolidays) -> 46148 | Q30: =WORKDAY(K30-1, L30+M30, IndHolidays) -> 46148 | T30: 3 | U30: =WORKDAY(Q30, T30, IndHolidays) -> 46153 | V30: 1.5 | W30: =WORKDAY(U30, V30, IndHolidays) -> 46154 | X30: =WORKDAY(W30,0, IndHolidays) -> 46154 | Y30: 3 | Z30: =WORKDAY(X30, Y30, IndHolidays) -> 46157 | AA30: =WORKDAY(Z30, 0, IndHolidays) -> 46157 | AB30: =WORKDAY(AA30, 0, IndHolidays) -> 46157 | AC30: =WORKDAY(AB30, 1, IndHolidays) -> 46160 | AD30: =WORKDAY(AC30, 0, IndHolidays) -> 46160 | AF30: =WORKDAY(AD30, AE30, IndHolidays) -> 46160 | AG30: 2 | AH30: =WORKDAY(AF30, AG30, IndHolidays) -> 46162 | AI30: 3 | AJ30: =WORKDAY(AH30, AI30, IndHolidays) -> 46167 | AK30: =WORKDAY(AJ30, 0, IndHolidays) -> 46167 | AL30: =WORKDAY(AK30, 1, IndHolidays) -> 46168 | AM30: =WORKDAY(AL30, 0, IndHolidays) -> 46168 | AO30: =WORKDAY(AM30, AN30, IndHolidays) -> 46168 | AP30: =AO30 -> 46168 | AQ30: =AP30 -> 46168 | AR30: =WORKDAY(AQ30, 1, IndHolidays) -> 46169 | AT30: =WORKDAY(AR30, AS30, IndHolidays) -> 46169 | AU30: 0 | AV30: =WORKDAY(AT30, AU30, IndHolidays) -> 46169 | AW30: 0 | AX30: =WORKDAY(AV30, AW30, IndHolidays) -> 46169 | AY30: =_xlfn.MINIFS(ReleaseTimeline!$A$2:$A$27, ReleaseTimeline!$A$2:$A$27, ">="&(MAX(AX30,AO30))) -> 46177 | AZ30: =VLOOKUP(AY30,ReleaseTimeline!$A$1:$E$27,2,FALSE) -> Release 12 | BA30: =WORKDAY(AZ30, 3, IndHolidays) -> #VALUE! | BB30: =VLOOKUP(AZ30,ReleaseTimeline!$B$2:$C$27,2,FALSE) -> 46184 | BC30: =WORKDAY(BB30, -5) -> 46177 | BD30: =(BB30 - P30) -> 36 | BF30: =(T30+Y30+AI30+AW30) -> 9
A31: 26 | B31: Content | F31: 46127 | H31: content\timeline.aspx.cs | I31: Pod 3 | J31: Rizwana | K31: =WORKDAY(F31,E31) -> 46127 | L31: 3 | M31: 0 | N31: 8817 | O31: =WORKDAY(K31-1, L31+M31, IndHolidays) -> 46129 | P31: =WORKDAY(K31-1, L31+M31, IndHolidays) -> 46129 | Q31: =WORKDAY(K31-1, L31+M31, IndHolidays) -> 46129 | S31: PR: 8817 raised on 5-May-26 | T31: 3 | U31: =WORKDAY(Q31, T31, IndHolidays) -> 46134 | V31: 1.5 | W31: =WORKDAY(U31, V31, IndHolidays) -> 46135 | X31: =WORKDAY(W31,0, IndHolidays) -> 46135 | Y31: 3 | Z31: =WORKDAY(X31, Y31, IndHolidays) -> 46140 | AA31: =WORKDAY(Z31, 0, IndHolidays) -> 46140 | AB31: =WORKDAY(AA31, 0, IndHolidays) -> 46140 | AC31: =WORKDAY(AB31, 1, IndHolidays) -> 46141 | AD31: =WORKDAY(AC31, 0, IndHolidays) -> 46141 | AF31: =WORKDAY(AD31, AE31, IndHolidays) -> 46141 | AG31: 2 | AH31: =WORKDAY(AF31, AG31, IndHolidays) -> 46146 | AI31: 3 | AJ31: =WORKDAY(AH31, AI31, IndHolidays) -> 46149 | AK31: =WORKDAY(AJ31, 0, IndHolidays) -> 46149 | AL31: =WORKDAY(AK31, 1, IndHolidays) -> 46150 | AM31: =WORKDAY(AL31, 0, IndHolidays) -> 46150 | AO31: =WORKDAY(AM31, AN31, IndHolidays) -> 46150 | AP31: =AO31 -> 46150 | AQ31: =AP31 -> 46150 | AR31: =WORKDAY(AQ31, 1, IndHolidays) -> 46153 | AT31: =WORKDAY(AR31, AS31, IndHolidays) -> 46153 | AU31: 0 | AV31: =WORKDAY(AT31, AU31, IndHolidays) -> 46153 | AW31: 0 | AX31: =WORKDAY(AV31, AW31, IndHolidays) -> 46153 | AY31: =_xlfn.MINIFS(ReleaseTimeline!$A$2:$A$27, ReleaseTimeline!$A$2:$A$27, ">="&(MAX(AX31,AO31))) -> 46163 | AZ31: =VLOOKUP(AY31,ReleaseTimeline!$A$1:$E$27,2,FALSE) -> Release 11 | BA31: =WORKDAY(AZ31, 3, IndHolidays) -> #VALUE! | BB31: =VLOOKUP(AZ31,ReleaseTimeline!$B$2:$C$27,2,FALSE) -> 46170 | BC31: =WORKDAY(BB31, -5) -> 46163 | BD31: =(BB31 - P31) -> 41 | BF31: =(T31+Y31+AI31+AW31) -> 9
A32: 27 | B32: Content | F32: =WORKDAY(Q29,1) -> 46149 | G32: 46146 | H32: content\captionedVideoItem.aspx.cs | I32: Pod 3 | J32: Ramesh | K32: 46146 | L32: 3 | M32: 0 | N32: 8804 | O32: =WORKDAY(K32-1, L32+M32, IndHolidays) -> 46148 | P32: =WORKDAY(K32-1, L32+M32, IndHolidays) -> 46148 | Q32: =WORKDAY(K32-1, L32+M32, IndHolidays) -> 46148 | T32: 3 | U32: =WORKDAY(Q32, T32, IndHolidays) -> 46153 | V32: 1.5 | W32: =WORKDAY(U32, V32, IndHolidays) -> 46154 | X32: =WORKDAY(W32,0, IndHolidays) -> 46154 | Y32: 3 | Z32: =WORKDAY(X32, Y32, IndHolidays) -> 46157 | AA32: =WORKDAY(Z32, 0, IndHolidays) -> 46157 | AB32: =WORKDAY(AA32, 0, IndHolidays) -> 46157 | AC32: =WORKDAY(AB32, 1, IndHolidays) -> 46160 | AD32: =WORKDAY(AC32, 0, IndHolidays) -> 46160 | AE32: 3 | AF32: =WORKDAY(AD32, AE32, IndHolidays) -> 46163 | AG32: 2 | AH32: =WORKDAY(AF32, AG32, IndHolidays) -> 46167 | AI32: 3 | AJ32: =WORKDAY(AH32, AI32, IndHolidays) -> 46171 | AK32: =WORKDAY(AJ32, 0, IndHolidays) -> 46171 | AL32: =WORKDAY(AK32, 1, IndHolidays) -> 46174 | AM32: =WORKDAY(AL32, 0, IndHolidays) -> 46174 | AN32: 1 | AO32: =WORKDAY(AM32, AN32, IndHolidays) -> 46176 | AP32: =AO32 -> 46176 | AQ32: =AP32 -> 46176 | AR32: =WORKDAY(AQ32, 1, IndHolidays) -> 46177 | AS32: 3 | AT32: =WORKDAY(AR32, AS32, IndHolidays) -> 46182 | AU32: 0 | AV32: =WORKDAY(AT32, AU32, IndHolidays) -> 46182 | AW32: 0 | AX32: =WORKDAY(AV32, AW32, IndHolidays) -> 46182 | AY32: =_xlfn.MINIFS(ReleaseTimeline!$A$2:$A$27, ReleaseTimeline!$A$2:$A$27, ">="&(MAX(AX32,AO32))) -> 46191 | AZ32: =VLOOKUP(AY32,ReleaseTimeline!$A$1:$E$27,2,FALSE) -> Release 13 | BA32: =WORKDAY(AZ32, 3, IndHolidays) -> #VALUE! | BB32: =VLOOKUP(AZ32,ReleaseTimeline!$B$2:$C$27,2,FALSE) -> 46198 | BC32: =WORKDAY(BB32, -5) -> 46191 | BD32: =(BB32 - P32) -> 50 | BF32: =(T32+Y32+AI32+AW32) -> 9
